# 7장

## 7.3 API 에러 핸들링

### 1. 타입 가드 활용하기

Axios 라이브러리에서는 Axios 에러에 대해 `isAxiosError` 타입 가드를 제공한다.  
이 타입 가드를 직접 사용할 수도 있지만, 서버 에러임을 명확하게 표시하고 서버에서 내려주는 에러 응답 객체에 대해서도 구체적으로 정의함으로써 에러 객체가 어떤 속성을 가졌는지 파악할 수 있다.

<br/>

서버에서 전달하는 공통 에러 객체에 대한 타입을 정의할 수 있다.

```ts
interface ErrorResponse {
  status: string;
  serverDateTime: string;
  errorCode: string;
  errorMessage: string;
}
```

ErrorResponse 인터페이스를 사용하여 처리해야 할 Axios 에러 형태는 `AxiosError<ErrorResponse>`로 표현할 수 있으며,  
아래와 같이 타입 가드를 명시적으로 작성할 수 있다.

```ts
function isServerError(error: unknown): error is AxiosError<ErrorResponse> {
  return axios.isAxiosError(error);
}
```

> 사용자 정의 타입 가드를 정의할 때는 타입 가드 함수의 반환 타입으로 `parameterName is Type` 형태로 타입 명제를 정의해주는 게 좋다. 이때 parameterName은 타입 가드 함수의 시그니처에 포함된 매개변수여야 한다.

```ts
const onClickDeleteHistoryButton = async (id: string) => {
  try {
    await axios.post("https://...", { id });

    alert("주문 내역이 삭제되었습니다.");
  } catch (error: unknown) {
    if (isServerError(e) && e.response && e.response.data.errorMessage) {
      // 서버 에러일 때의 처리임을 명시적으로 알 수 있다.
      setErrorMessage(e.response.data.errorMessage);
      return;
    }

    setErrorMessage("일시적인 에러가 발생했습니다. 잠시 후 다시 시도해주세요.");
  }
};
```

### 2. 에러 서브클래싱하기

**서브클래싱(Subclasssing)**  
기존(=상위,부모) 클래스를 확장하여 새로운(=하위,자식) 클래스를 만드는 과정을 말한다.  
새로운 클래스는 상위 클래스의 모든 속성과 메서드를 상속받아 사용할 수 있고 추가적인 속성과 메서드를 정의할 수 있다.

<br/>

ex. 주문 내역을 요청할 때 에러가 발생하면 에러 메시지를 얼럿을 사용하여 사용자에게 표시해주기

```ts
const getOrderHistory = async (page: number): Promise<History> => {
  try {
    const { data } = await axios.get(`https://some.site?page=${page}`);
    const history = await JSON.parse(data);

    return history;
  } catch (error) {
    alert(error.message);
  }
};
```

-> 사용자는 에러메세지를 보고 어떤 에러가 발생한 것인지 판단할 수 있지만, 개발자 입장에서는 판단할 수 없다.

서브클래싱을 활용하면 에러가 발생했을 때 코드상에서 어떤 에러인지 바로 확인 할 수 있다.  
에러 인스턴스가 무엇인지에 따라 에러 처리 방식을 다르게 구현할 수 있다.

```ts
class OrderHttpError extends Error {
  // HTTP 요청이 실패했을 때 해당 응답을 저장함
  private readonly privateResponse: AxiosResponse<ErrorResponse> | undefined;

  constructor(message?: string, response?: AxiosResponse<ErrorResponse>) {
    super(message);
    this.name = "OrderHttpError";
    this.privateResponse = response;
  }

  // privateResponse의 getter 메소드: 외부에서 privateResponse에 접근 가능
  get response(): AxiosResponse<ErrorResponse> | undefined {
    return this.privateResponse;
  }
}

class NetworkError extends Error {
  constructor(message = "") {
    super(message);
    this.name = "NetwordError";
  }
}

class UnauthorizedError extends Error {
  constructor(message: string, response?: AxiosResponse<ErrorResponse>) {
    super(message, response);
    this.name = "UnauthorizedError";
  }
}
```

```ts
const httpErrorHandler = (
  error: AxiosError<ErrorResponse> | Error
): Promise<Error> => {
  // 나중에 반환할 Promise를 저장하는 변수
  let promiseError: Promise<Error>;

  // 주어진 오류가 AxiosError인지 확인
  if (axios.isAxiosError(error)) {
    // 오류 코드가 "ECONNABORTED"인 경우 시간 초과 오류를 나타내므로,
    // TimeoutError 예외를 생성하고 해당 Promise를 거부함
    if (Object.is(error.code, "ECONNABORTED")) {
      promiseError = Promise.reject(new TimeoutError());
    }
    // 오류 메시지가 "Network Error"인 경우 네트워크 오류를 나타내므로,
    // NetworkError 예외를 생성하고 해당 Promise를 거부함
    else if (Object.is(error.message, "Network Error")) {
      promiseError = Promise.reject(new NetworkError(""));
    }
    // 그 외의 경우
    else {
      const { response } = error as AxiosError<ErrorResponse>;

      switch (response?.status) {
        // 상태 코드가 "UNAUTHORIZED"인 경우 권한 없음 오류를 나타내므로,
        // UNAUTHORIZED 예외를 생성하고 해당 Promise를 거부함
        case HttpStatusCode.UNAUTHORIZED:
          promiseError = Promise.reject(
            new UnauthorizedError(response?.data.message, response)
          );
          break;
        // 디폴트값: OrderHttpError 예외를 생성하고 해당 Promise를 거부함
        default:
          promiseError = Promise.reject(
            new OrderHttpError(response?.data.message, response)
          );
      }
    }
  }
  // AxiosError가 아닌 경우, 주어진 오류를 그대로 반환함
  else {
    promiseError = Promise.reject(error);
  }

  return promiseError;
};
```

요청 코드에서는 아래와 같이 활용할 수 있다.

```ts
const onActionError = (
  error: unknown,
  params?: Omit<AlertPopup, "type" | "message">
) => {
  if (error instanceof UnauthorizedError) {
    onUnauthorizedError(
      error.message,
      errorCallback?.onUnauthorizedErrorCallback
    );
  } else if (error instanceof NetworkError) {
    alert("네트워크 연결이 원활하지 않습니다. 잠시 후 다시 시도해주세요.", {
      onClose: errorCallback?.onNetworkErrorCallback,
    });
  } else if (error instanceof OrderHttpError) {
    alert(error.message, params);
  } else if (error instanceof Error) {
    alert(error.message, params);
  } else {
    alert(defaultHttpErrorMessage, params);
  }
};

const getOrderHistory = async (page: number): Promise<History> => {
  try {
    const { data } = await fetchOrderHistory({ page });
    const history = await JSON.parse(data);

    return history;
  } catch (error) {
    onActionError(error);
  }
};
```

> **ECONNABORTED**  
> 클라이언트가 서버에 HTTP 요청을 보내고 서버가 이를 처리하는 동안 네트워크 연결이 유지되는 상황에서, 서버가 요청을 처리하는 데 오랜 시간이 걸리거나 서버가 응답을 제대로 보내지 못할 경우, 클라이언트는 이 오류 코드를 받을 수 있다. 보통 요청이 시스템에서 처리되지 못했거나 시간 초과로 인해 중단된 경우에 발생한다.

### 3. 인터셉터를 활용한 에러 처리

Axios 같은 페칭 라이브러리는 인터셉터(interceptors) 기능을 제공한다. 이를 사용하면 HTTP 에러에 일관된 로직을 적용할 수 있다.

```ts
const httpErrorHandler = (
  error: AxiosError<ErrorResponse> | Error
): Promise<Error> => {
  (error) => {
    // 401 에러인 경우 로그인 페이지로 이동
    if (error.response && error.response.status === 401) {
      window.location.href = `${backOfficeAuthHost}/login?targetUrl=${window.location.href}`;
    }
    return Promise.reject(error);
  };
};

orderApiRequester.interceptors.response.use(
  (response: AxiosResponse) => response,
  httpErrorHandler
);
```

### 4. 에러 바운더리를 활용한 에러 처리

**에러 바운더리**  
리액트 컴포넌트 트리에서 에러가 발생할 때 공통으로 에러를 처리하는 리액트 컴포넌트.  
에러 바운더리를 사용하면 리액트 컴포넌트 트리 하위에 있는 컴포넌트에서 발생한 에러를 캐치하고, 해당 에러를 가장 가까운 부모 에러 바운더리에서 처리하게 할 수 있다.  
에러 바운더리는 에러가 발생한 컴포넌트 대신에 에러 처리를 하거나 예상치 못한 에러를 공통 처리할 때 사용할 수 있다.

<br/>
OrderHistoryPage 컴포넌트 내에서 처리되지 않은 에러가 있을 때 에러 바운더리에서 에러 페이지를 노출한다.

```ts
import React, { ErrorInfo } from "react";
import ErrorPage from "pages/ErrorPage";

interface ErrorBoundaryProps {}

interface ErrorBoundaryState {
  hasError: boolean;
}

class ErrorBoundary extends React.Component<
  ErrorBoundaryProps,
  ErrorBoundaryState
> {
  constructor(props: ErrorBoundaryProps) {
    super(props);
    this.state = { hasError: false };
  }

  static getDerivedStateFromError(): ErrorBoundaryState {
    return { hasError: true };
  }

  // 하위 컴포넌트에서 발생한 오류를 캐치함
  // 내장 메서드
  componentDidCatch(error: Error, errorInfo: ErrorInfo): void {
    this.setState({ hasError: true });
    console.error(error, errorInfo);
  }

  // hasError 상태에 따라 렌더링할 내용을 결정함
  // React 클래스 컴포넌트에서 내장된 메서드, 해당 컴포넌트의 UI를 렌더링
  render(): React.ReactNode {
    const { children } = this.props;
    const { hasError } = this.state;
    return hasError ? <ErrorPage /> : children;
  }
}

const App = () => {
  return (
    // ErrorBoundary 컴포넌트는 OrderHistoryPage 컴포넌트의 부모로써,
    // OrderHistoryPage 컴포넌트에서 발생한 오류를 처리함
    <ErrorBoundary>
      <OrderHistoryPage />
    </ErrorBoundary>
  );
};
```

### 5. 상태 관리 라이브러리에서의 에러 처리

(작성중..)

### 6. react-query를 활용한 에러 처리

react-query나 swr과 같은 데이터 페칭 라이브러리를 사용하면 요청에 대한 상태를 반환해 주기 때문에 요청 상태를 확인하기 쉽다.

```ts
const JobComponent: React.FC = () => {
  const { isError, error, isLoading, data } = useFetchJobList();

  if(isError) {
    return <div>{`${error.message}가 발생했습니다. 나중에 다시 시도해주세요.`</div>;
  }

  if(isLoading) {
    return <div>로딩 중입니다.</div>
  }

  return <>{data.map((job)=> <JobItem key={job.id} job={job} />)}</>
};
```

### 7. 그 밖의 에러 처리

**200번 대의 성공 응답에 대한 에러 처리**  
-> HTTP 요청은 성공했지만, 응답이 예상과 다른 경우  
-> ex. 서버로의 요청은 성공했지만 서버에서 반환한 데이터의 형식이나 내용이 예상과 다르거나, 클라이언트가 처리할 수 없는 상황

장바구니에서 주문을 생성하는 API가 아래와 같은 커스텀 에러를 반환함

```ts
httpStatus: 200
{
  "status": "C20005", // 성공인 경우 "SUCCESS"를 응답
  "message": "장바구니에 품절된 메뉴가 있습니다."
}
```

이 에러를 처리하기 위해 요청 함수 내에서 조건문으로 status(상태)를 비교할 수 있다.

```ts
const successHandler = (response: CreateOrderResponse) => {
  if (response.status === "SUCCESS") {
    // 성공 시 진행할 로직을 추가한다
    return;
  }
  throw new CustomError(response.status, response.message);
};

const createOrder = (data: CreateOrderData) => {
  try {
    const response = apiRequester.post("https://...", data);

    successHandler(response);
  } catch (error) {
    errorHandler(error);
  }
};
```

그러나 위와 같은 코드는 만약 처리해야 하는 API가 많을 때 매번 `if (response.status === "SUCCESS")` 구문을 추가해야 하는 단점이 있다.  
커스텀 에러를 사용하고 있는 요청을 일괄적으로 에러로 처리하고 싶다면 Axios 등의 라이브러리 기능을 활용하면 된다.  
특정 호스트에 대한 API requester를 별도로 선언하고 상태 코드 비교 로직을 인터셉터에 추가할 수 있다.

```ts
export const apiRequester: AxiosInstance = axios.create({
  baseURL: orderApiBaseUrl,
  ...defaultConfig,
});

export const httpSuccessHandler = (response: AxiosResponse) => {
  if (response.data.status !== "SUCCESS") {
    throw new CustomError(response?.data.message, response);
  }
  return response;
};

// 인터셉터에서 커스텀 에러를 판단하고 에러를 던짐
apiRequester.interceptors.response.use(httpSuccessHandler, httpErrorHandler);

const createOrder = (data: CreateOrderData) => {
  try {
    const response = apiRequester.post("http://...", data);

    successHandler(response);
  } catch (error) {
    // status가 SUCCESS가 아닌 경우 에러로 전달된다.
    errorHandler(error);
  }
};
```
